2022-06-04 21:22:46,845 ERROR: Exception on /admin/list_categories [POST] [in /home/ulrik/Git/Logger/venv/lib/python3.8/site-packages/flask/app.py:1455]
Traceback (most recent call last):
  File "/home/ulrik/Git/Logger/venv/lib/python3.8/site-packages/sqlalchemy/engine/base.py", line 1819, in _execute_context
    self.dialect.do_execute(
  File "/home/ulrik/Git/Logger/venv/lib/python3.8/site-packages/sqlalchemy/engine/default.py", line 732, in do_execute
    cursor.execute(statement, parameters)
sqlite3.IntegrityError: UNIQUE constraint failed: log_categories.name

The above exception was the direct cause of the following exception:

Traceback (most recent call last):
  File "/home/ulrik/Git/Logger/venv/lib/python3.8/site-packages/flask/app.py", line 2077, in wsgi_app
    response = self.full_dispatch_request()
  File "/home/ulrik/Git/Logger/venv/lib/python3.8/site-packages/flask/app.py", line 1525, in full_dispatch_request
    rv = self.handle_user_exception(e)
  File "/home/ulrik/Git/Logger/venv/lib/python3.8/site-packages/flask/app.py", line 1523, in full_dispatch_request
    rv = self.dispatch_request()
  File "/home/ulrik/Git/Logger/venv/lib/python3.8/site-packages/flask/app.py", line 1509, in dispatch_request
    return self.ensure_sync(self.view_functions[rule.endpoint])(**req.view_args)
  File "/home/ulrik/Git/Logger/app/admin/routes.py", line 78, in list_categories
    db.session.commit()
  File "<string>", line 2, in commit
  File "/home/ulrik/Git/Logger/venv/lib/python3.8/site-packages/sqlalchemy/orm/session.py", line 1435, in commit
    self._transaction.commit(_to_root=self.future)
  File "/home/ulrik/Git/Logger/venv/lib/python3.8/site-packages/sqlalchemy/orm/session.py", line 829, in commit
    self._prepare_impl()
  File "/home/ulrik/Git/Logger/venv/lib/python3.8/site-packages/sqlalchemy/orm/session.py", line 808, in _prepare_impl
    self.session.flush()
  File "/home/ulrik/Git/Logger/venv/lib/python3.8/site-packages/sqlalchemy/orm/session.py", line 3367, in flush
    self._flush(objects)
  File "/home/ulrik/Git/Logger/venv/lib/python3.8/site-packages/sqlalchemy/orm/session.py", line 3507, in _flush
    transaction.rollback(_capture_exception=True)
  File "/home/ulrik/Git/Logger/venv/lib/python3.8/site-packages/sqlalchemy/util/langhelpers.py", line 70, in __exit__
    compat.raise_(
  File "/home/ulrik/Git/Logger/venv/lib/python3.8/site-packages/sqlalchemy/util/compat.py", line 207, in raise_
    raise exception
  File "/home/ulrik/Git/Logger/venv/lib/python3.8/site-packages/sqlalchemy/orm/session.py", line 3467, in _flush
    flush_context.execute()
  File "/home/ulrik/Git/Logger/venv/lib/python3.8/site-packages/sqlalchemy/orm/unitofwork.py", line 456, in execute
    rec.execute(self)
  File "/home/ulrik/Git/Logger/venv/lib/python3.8/site-packages/sqlalchemy/orm/unitofwork.py", line 630, in execute
    util.preloaded.orm_persistence.save_obj(
  File "/home/ulrik/Git/Logger/venv/lib/python3.8/site-packages/sqlalchemy/orm/persistence.py", line 245, in save_obj
    _emit_insert_statements(
  File "/home/ulrik/Git/Logger/venv/lib/python3.8/site-packages/sqlalchemy/orm/persistence.py", line 1238, in _emit_insert_statements
    result = connection._execute_20(
  File "/home/ulrik/Git/Logger/venv/lib/python3.8/site-packages/sqlalchemy/engine/base.py", line 1631, in _execute_20
    return meth(self, args_10style, kwargs_10style, execution_options)
  File "/home/ulrik/Git/Logger/venv/lib/python3.8/site-packages/sqlalchemy/sql/elements.py", line 325, in _execute_on_connection
    return connection._execute_clauseelement(
  File "/home/ulrik/Git/Logger/venv/lib/python3.8/site-packages/sqlalchemy/engine/base.py", line 1498, in _execute_clauseelement
    ret = self._execute_context(
  File "/home/ulrik/Git/Logger/venv/lib/python3.8/site-packages/sqlalchemy/engine/base.py", line 1862, in _execute_context
    self._handle_dbapi_exception(
  File "/home/ulrik/Git/Logger/venv/lib/python3.8/site-packages/sqlalchemy/engine/base.py", line 2043, in _handle_dbapi_exception
    util.raise_(
  File "/home/ulrik/Git/Logger/venv/lib/python3.8/site-packages/sqlalchemy/util/compat.py", line 207, in raise_
    raise exception
  File "/home/ulrik/Git/Logger/venv/lib/python3.8/site-packages/sqlalchemy/engine/base.py", line 1819, in _execute_context
    self.dialect.do_execute(
  File "/home/ulrik/Git/Logger/venv/lib/python3.8/site-packages/sqlalchemy/engine/default.py", line 732, in do_execute
    cursor.execute(statement, parameters)
sqlalchemy.exc.IntegrityError: (sqlite3.IntegrityError) UNIQUE constraint failed: log_categories.name
[SQL: INSERT INTO log_categories (name) VALUES (?)]
[parameters: ('hej',)]
(Background on this error at: https://sqlalche.me/e/14/gkpj)
2022-06-04 21:24:01,787 INFO: Logger startup [in /home/ulrik/Git/Logger/app/__init__.py:58]
2022-06-04 21:24:37,723 INFO: Logger startup [in /home/ulrik/Git/Logger/app/__init__.py:58]
2022-06-04 21:34:10,022 INFO: Logger startup [in /home/ulrik/Git/Logger/app/__init__.py:58]
2022-06-04 21:35:14,545 INFO: Logger startup [in /home/ulrik/Git/Logger/app/__init__.py:58]
2022-06-04 21:37:05,753 INFO: Logger startup [in /home/ulrik/Git/Logger/app/__init__.py:58]
2022-06-04 21:37:27,717 INFO: Logger startup [in /home/ulrik/Git/Logger/app/__init__.py:58]
2022-06-04 21:38:00,495 INFO: Logger startup [in /home/ulrik/Git/Logger/app/__init__.py:58]
2022-06-04 21:38:01,296 ERROR: Exception on /admin/list_categories/delete [POST] [in /home/ulrik/Git/Logger/venv/lib/python3.8/site-packages/flask/app.py:1455]
Traceback (most recent call last):
  File "/home/ulrik/Git/Logger/venv/lib/python3.8/site-packages/flask/app.py", line 2077, in wsgi_app
    response = self.full_dispatch_request()
  File "/home/ulrik/Git/Logger/venv/lib/python3.8/site-packages/flask/app.py", line 1525, in full_dispatch_request
    rv = self.handle_user_exception(e)
  File "/home/ulrik/Git/Logger/venv/lib/python3.8/site-packages/flask/app.py", line 1523, in full_dispatch_request
    rv = self.dispatch_request()
  File "/home/ulrik/Git/Logger/venv/lib/python3.8/site-packages/flask/app.py", line 1509, in dispatch_request
    return self.ensure_sync(self.view_functions[rule.endpoint])(**req.view_args)
  File "/home/ulrik/Git/Logger/app/admin/routes.py", line 85, in del_category
    test = request.form.get()
TypeError: get() missing 1 required positional argument: 'key'
2022-06-04 21:38:42,530 INFO: Logger startup [in /home/ulrik/Git/Logger/app/__init__.py:58]
2022-06-04 21:39:18,823 INFO: Logger startup [in /home/ulrik/Git/Logger/app/__init__.py:58]
2022-06-04 21:41:10,544 INFO: Logger startup [in /home/ulrik/Git/Logger/app/__init__.py:58]
2022-06-04 21:41:12,837 ERROR: Exception on /admin/list_categories/delete [POST] [in /home/ulrik/Git/Logger/venv/lib/python3.8/site-packages/flask/app.py:1455]
Traceback (most recent call last):
  File "/home/ulrik/Git/Logger/venv/lib/python3.8/site-packages/flask/app.py", line 2077, in wsgi_app
    response = self.full_dispatch_request()
  File "/home/ulrik/Git/Logger/venv/lib/python3.8/site-packages/flask/app.py", line 1525, in full_dispatch_request
    rv = self.handle_user_exception(e)
  File "/home/ulrik/Git/Logger/venv/lib/python3.8/site-packages/flask/app.py", line 1523, in full_dispatch_request
    rv = self.dispatch_request()
  File "/home/ulrik/Git/Logger/venv/lib/python3.8/site-packages/flask/app.py", line 1509, in dispatch_request
    return self.ensure_sync(self.view_functions[rule.endpoint])(**req.view_args)
  File "/home/ulrik/Git/Logger/app/admin/routes.py", line 85, in del_category
    test = request.form()
TypeError: 'ImmutableMultiDict' object is not callable
2022-06-04 21:42:15,960 INFO: Logger startup [in /home/ulrik/Git/Logger/app/__init__.py:58]
2022-06-04 21:44:07,033 INFO: Logger startup [in /home/ulrik/Git/Logger/app/__init__.py:58]
2022-06-04 21:45:08,538 INFO: Logger startup [in /home/ulrik/Git/Logger/app/__init__.py:58]
2022-06-04 21:45:48,050 INFO: Logger startup [in /home/ulrik/Git/Logger/app/__init__.py:58]
2022-06-04 21:46:46,216 INFO: Logger startup [in /home/ulrik/Git/Logger/app/__init__.py:58]
2022-06-04 21:47:44,841 INFO: Logger startup [in /home/ulrik/Git/Logger/app/__init__.py:58]
2022-06-04 21:48:01,619 INFO: Logger startup [in /home/ulrik/Git/Logger/app/__init__.py:58]
2022-06-04 21:48:09,457 INFO: Logger startup [in /home/ulrik/Git/Logger/app/__init__.py:58]
2022-06-04 21:48:17,365 INFO: Logger startup [in /home/ulrik/Git/Logger/app/__init__.py:58]
2022-06-04 21:48:30,614 INFO: Logger startup [in /home/ulrik/Git/Logger/app/__init__.py:58]
2022-06-04 21:48:36,427 INFO: Logger startup [in /home/ulrik/Git/Logger/app/__init__.py:58]
2022-06-04 21:53:20,581 INFO: Logger startup [in /home/ulrik/Git/Logger/app/__init__.py:58]
2022-06-04 21:57:30,260 INFO: Logger startup [in /home/ulrik/Git/Logger/app/__init__.py:58]
2022-06-05 16:19:00,429 INFO: Logger startup [in /home/ulrik/Git/Logger/app/__init__.py:58]
2022-06-05 16:58:40,689 INFO: Logger startup [in /home/ulrik/Git/Logger/app/__init__.py:58]
